<?xml version="1.0" encoding="UTF-8"?>
<!-- Generated by org.testng.reporters.JUnitReportReporter -->
<testsuite hostname="W-7FM3M13" failures="3" tests="6" name="com.test.testcases.PlatformSignUpTest" time="398.639" errors="0" timestamp="2020-11-12T21:57:43 IST" skipped="3">
  <testcase classname="com.test.testcases.PlatformSignUpTest" name="signUpConversationalAI" time="70.123">
    <failure message="Success Message does not exist" type="java.lang.AssertionError">
      <![CDATA[java.lang.AssertionError: Success Message does not exist
at org.testng.Assert.fail(Assert.java:97)
at com.utils.GenericUtils.checkFieldExist(GenericUtils.java:192)
at com.pages.SignUpCAIPage.verifySuccessMessage(SignUpCAIPage.java:141)
at com.test.testcases.PlatformSignUpTest.signUpConversationalAI(PlatformSignUpTest.java:62)
at java.base/jdk.internal.reflect.NativeMethodAccessorImpl.invoke0(Native Method)
at java.base/jdk.internal.reflect.NativeMethodAccessorImpl.invoke(NativeMethodAccessorImpl.java:62)
at java.base/jdk.internal.reflect.DelegatingMethodAccessorImpl.invoke(DelegatingMethodAccessorImpl.java:43)
at java.base/java.lang.reflect.Method.invoke(Method.java:566)
at org.testng.internal.MethodInvocationHelper.invokeMethod(MethodInvocationHelper.java:135)
at org.testng.internal.TestInvoker.invokeMethod(TestInvoker.java:598)
at org.testng.internal.TestInvoker.retryFailed(TestInvoker.java:214)
at org.testng.internal.MethodRunner.runInSequence(MethodRunner.java:58)
at org.testng.internal.TestInvoker$MethodInvocationAgent.invoke(TestInvoker.java:821)
at org.testng.internal.TestInvoker.invokeTestMethods(TestInvoker.java:147)
at org.testng.internal.TestMethodWorker.invokeTestMethods(TestMethodWorker.java:146)
at org.testng.internal.TestMethodWorker.run(TestMethodWorker.java:128)
at java.base/java.util.ArrayList.forEach(ArrayList.java:1540)
at org.testng.TestRunner.privateRun(TestRunner.java:767)
at org.testng.TestRunner.run(TestRunner.java:588)
at org.testng.SuiteRunner.runTest(SuiteRunner.java:384)
at org.testng.SuiteRunner.runSequentially(SuiteRunner.java:378)
at org.testng.SuiteRunner.privateRun(SuiteRunner.java:337)
at org.testng.SuiteRunner.run(SuiteRunner.java:286)
at org.testng.SuiteRunnerWorker.runSuite(SuiteRunnerWorker.java:53)
at org.testng.SuiteRunnerWorker.run(SuiteRunnerWorker.java:96)
at org.testng.TestNG.runSuitesSequentially(TestNG.java:1214)
at org.testng.TestNG.runSuitesLocally(TestNG.java:1136)
at org.testng.TestNG.runSuites(TestNG.java:1066)
at org.testng.TestNG.run(TestNG.java:1034)
at org.testng.remote.AbstractRemoteTestNG.run(AbstractRemoteTestNG.java:115)
at org.testng.remote.RemoteTestNG.initAndRun(RemoteTestNG.java:251)
at org.testng.remote.RemoteTestNG.main(RemoteTestNG.java:77)
]]>
    </failure>
  </testcase> <!-- signUpConversationalAI -->
  <system-out/>
  <testcase classname="com.test.testcases.PlatformSignUpTest" name="signUpConversationalAI" time="67.537">
    <skipped/>
  </testcase> <!-- signUpConversationalAI -->
  <system-out/>
  <testcase classname="com.test.testcases.PlatformSignUpTest" name="signUpConversationalAI" time="63.992">
    <skipped/>
  </testcase> <!-- signUpConversationalAI -->
  <system-out/>
  <testcase classname="com.test.testcases.PlatformSignUpTest" name="signUpConversationalAI" time="68.602">
    <skipped/>
  </testcase> <!-- signUpConversationalAI -->
  <system-out/>
  <testcase classname="com.test.testcases.PlatformSignUpTest" name="signUpConversationalAI" time="59.678">
    <failure message="Success Message does not exist" type="java.lang.AssertionError">
      <![CDATA[java.lang.AssertionError: Success Message does not exist
at org.testng.Assert.fail(Assert.java:97)
at com.utils.GenericUtils.checkFieldExist(GenericUtils.java:192)
at com.pages.SignUpCAIPage.verifySuccessMessage(SignUpCAIPage.java:141)
at com.test.testcases.PlatformSignUpTest.signUpConversationalAI(PlatformSignUpTest.java:62)
at java.base/jdk.internal.reflect.NativeMethodAccessorImpl.invoke0(Native Method)
at java.base/jdk.internal.reflect.NativeMethodAccessorImpl.invoke(NativeMethodAccessorImpl.java:62)
at java.base/jdk.internal.reflect.DelegatingMethodAccessorImpl.invoke(DelegatingMethodAccessorImpl.java:43)
at java.base/java.lang.reflect.Method.invoke(Method.java:566)
at org.testng.internal.MethodInvocationHelper.invokeMethod(MethodInvocationHelper.java:135)
at org.testng.internal.TestInvoker.invokeMethod(TestInvoker.java:598)
at org.testng.internal.TestInvoker.retryFailed(TestInvoker.java:214)
at org.testng.internal.MethodRunner.runInSequence(MethodRunner.java:58)
at org.testng.internal.TestInvoker$MethodInvocationAgent.invoke(TestInvoker.java:821)
at org.testng.internal.TestInvoker.invokeTestMethods(TestInvoker.java:147)
at org.testng.internal.TestMethodWorker.invokeTestMethods(TestMethodWorker.java:146)
at org.testng.internal.TestMethodWorker.run(TestMethodWorker.java:128)
at java.base/java.util.ArrayList.forEach(ArrayList.java:1540)
at org.testng.TestRunner.privateRun(TestRunner.java:767)
at org.testng.TestRunner.run(TestRunner.java:588)
at org.testng.SuiteRunner.runTest(SuiteRunner.java:384)
at org.testng.SuiteRunner.runSequentially(SuiteRunner.java:378)
at org.testng.SuiteRunner.privateRun(SuiteRunner.java:337)
at org.testng.SuiteRunner.run(SuiteRunner.java:286)
at org.testng.SuiteRunnerWorker.runSuite(SuiteRunnerWorker.java:53)
at org.testng.SuiteRunnerWorker.run(SuiteRunnerWorker.java:96)
at org.testng.TestNG.runSuitesSequentially(TestNG.java:1214)
at org.testng.TestNG.runSuitesLocally(TestNG.java:1136)
at org.testng.TestNG.runSuites(TestNG.java:1066)
at org.testng.TestNG.run(TestNG.java:1034)
at org.testng.remote.AbstractRemoteTestNG.run(AbstractRemoteTestNG.java:115)
at org.testng.remote.RemoteTestNG.initAndRun(RemoteTestNG.java:251)
at org.testng.remote.RemoteTestNG.main(RemoteTestNG.java:77)
]]>
    </failure>
  </testcase> <!-- signUpConversationalAI -->
  <system-out/>
  <testcase classname="com.test.testcases.PlatformSignUpTest" name="signUpConversationalAI" time="68.707">
    <failure message="Success Message does not exist" type="java.lang.AssertionError">
      <![CDATA[java.lang.AssertionError: Success Message does not exist
at org.testng.Assert.fail(Assert.java:97)
at com.utils.GenericUtils.checkFieldExist(GenericUtils.java:192)
at com.pages.SignUpCAIPage.verifySuccessMessage(SignUpCAIPage.java:141)
at com.test.testcases.PlatformSignUpTest.signUpConversationalAI(PlatformSignUpTest.java:62)
at java.base/jdk.internal.reflect.NativeMethodAccessorImpl.invoke0(Native Method)
at java.base/jdk.internal.reflect.NativeMethodAccessorImpl.invoke(NativeMethodAccessorImpl.java:62)
at java.base/jdk.internal.reflect.DelegatingMethodAccessorImpl.invoke(DelegatingMethodAccessorImpl.java:43)
at java.base/java.lang.reflect.Method.invoke(Method.java:566)
at org.testng.internal.MethodInvocationHelper.invokeMethod(MethodInvocationHelper.java:135)
at org.testng.internal.TestInvoker.invokeMethod(TestInvoker.java:598)
at org.testng.internal.TestInvoker.retryFailed(TestInvoker.java:214)
at org.testng.internal.MethodRunner.runInSequence(MethodRunner.java:58)
at org.testng.internal.TestInvoker$MethodInvocationAgent.invoke(TestInvoker.java:821)
at org.testng.internal.TestInvoker.invokeTestMethods(TestInvoker.java:147)
at org.testng.internal.TestMethodWorker.invokeTestMethods(TestMethodWorker.java:146)
at org.testng.internal.TestMethodWorker.run(TestMethodWorker.java:128)
at java.base/java.util.ArrayList.forEach(ArrayList.java:1540)
at org.testng.TestRunner.privateRun(TestRunner.java:767)
at org.testng.TestRunner.run(TestRunner.java:588)
at org.testng.SuiteRunner.runTest(SuiteRunner.java:384)
at org.testng.SuiteRunner.runSequentially(SuiteRunner.java:378)
at org.testng.SuiteRunner.privateRun(SuiteRunner.java:337)
at org.testng.SuiteRunner.run(SuiteRunner.java:286)
at org.testng.SuiteRunnerWorker.runSuite(SuiteRunnerWorker.java:53)
at org.testng.SuiteRunnerWorker.run(SuiteRunnerWorker.java:96)
at org.testng.TestNG.runSuitesSequentially(TestNG.java:1214)
at org.testng.TestNG.runSuitesLocally(TestNG.java:1136)
at org.testng.TestNG.runSuites(TestNG.java:1066)
at org.testng.TestNG.run(TestNG.java:1034)
at org.testng.remote.AbstractRemoteTestNG.run(AbstractRemoteTestNG.java:115)
at org.testng.remote.RemoteTestNG.initAndRun(RemoteTestNG.java:251)
at org.testng.remote.RemoteTestNG.main(RemoteTestNG.java:77)
]]>
    </failure>
  </testcase> <!-- signUpConversationalAI -->
  <system-out/>
</testsuite> <!-- com.test.testcases.PlatformSignUpTest -->
